Workbook

Sheet 正文注文
A1: 卷数 | B1: 文类名 | C1: 部类名 | D1: 作品名 | E1: 正文 | F1: 注文 | G1: 注文类型
A2: 卷一 | B2: 赋甲 | C2: 京都上 | D2: 两都赋 | E2: 或曰：赋者，古诗之流也。 | F2: 《毛诗序》曰：诗有六义焉，二曰赋。故赋为古诗之流也。诸引文证，皆举先以明后，以示作者必有所祖述也。他皆类此。
A3: 卷一 | B3: 赋甲 | C3: 京都上 | D3: 两都赋 | E3: 昔成康没而颂声寝，王泽竭而诗不作。 | F3: 言周道既微，雅颂并废也。《史记》曰：周武王太子诵立，是为成王。成王太子钊立，是为康王。《毛诗序》曰：颂者，以其成功告于神明者也。《乐稽耀嘉》曰：仁义所生为王。《毛诗序》曰：止乎礼义，先王之泽也。然则作诗禀乎先王之泽，故王泽竭而诗不作。作，兴也。《孟子》曰：王者之迹息而诗亡。
A4: 卷一 | B4: 赋甲 | C4: 京都上 | D4: 两都赋 | E4: 大汉初定，日不暇给。 | F4: 《汉书》曰：高祖，姓刘氏，立为汉王，灭项羽，即皇帝位。荀悦曰：讳邦，字季。《史记》曰：虽受命，而日有不暇给也。
A5: 卷一 | B5: 赋甲 | C5: 京都上 | D5: 两都赋 | E5: 至于武宣之世，乃崇礼官，考文章， | F5: 《汉书》曰：孝武皇帝，景帝中子。荀悦曰：讳彻。《汉书》曰：孝宣帝，武帝曾孙，戾太子孙。荀悦曰：讳询，字次卿。
A6: 卷一 | B6: 赋甲 | C6: 京都上 | D6: 两都赋 | E6: 内设金马、石渠之署，外兴乐府协律之事， | F6: 《史记》曰：金马门者，宦者署门，傍有铜马，故谓之曰金马门。《三辅故事》曰：石渠阁在大秘殿北，以阁秘书。《汉书》曰：武帝定郊祀之礼，乃立乐府，以李延年为协律都尉。
A7: 卷一 | B7: 赋甲 | C7: 京都上 | D7: 两都赋 | E7: 以兴废继绝，润色鸿业。 | F7: 言能发起遗文，以光赞大业也。《论语》，子曰：兴灭国，继绝世。然文虽出彼而意微殊，不可以文害意。他皆类此。《论语》，子曰：东里子产润色之。《剧秦美新》曰：制成《六经》，洪业也。
A8: 卷一 | B8: 赋甲 | C8: 京都上 | D8: 两都赋 | E8: 是以众庶悦豫，福应尤盛，《白麟》《赤鴈》《芝房》《宝鼎》之歌，荐于郊庙。 | F8: 《汉书·武纪》曰：行幸雍，获白麟，作《白麟》之歌。又曰：行幸东海，获赤鴈，作《朱鴈》之歌。又曰：甘泉宫内产芝，九茎连叶，作《芝房歌》。又曰：得宝鼎后土祠傍，作《宝鼎》之歌。
A9: 卷一 | B9: 赋甲 | C9: 京都上 | D9: 两都赋 | E9: 神雀五凤甘露黄龙之瑞，以为年纪。 | F9: 《汉书·宣纪》曰：神雀元年。应劭曰：前年神雀集长乐宫，故改年也。又曰：五凤元年。应劭曰：先者，凤皇五至，因以改元。又甘灵元年，诏曰：乃者，凤皇至，甘露降，故以名元年。又曰：黄龙元年。应劭曰：先是黄龙见新丰，因以改元焉。
A10: 卷一 | B10: 赋甲 | C10: 京都上 | D10: 两都赋 | E10: 故言语侍从之臣，若司马相如虞丘寿王东方朔枚臯王襃刘向之属，朝夕论思，日月献纳； | F10: 《汉书》曰：司马相如，字长卿，为武骑常侍。又曰：虞丘寿王，字子贡，以善格五召待诏，迁为侍中中书，又曰：东方朔，字曼倩，上书自称举，上伟之，令待诏公车，后拜为太中大夫给事中。又曰：枚臯，字少孺，上书北阙，自称枚乘之子，上得大喜，召入见待诏，拜为郎。又曰，王襃，字子渊，上令襃待诏，襃等数从猎，擢为谏大夫。又曰：刘向，字子政，为辇郎，迁中垒校尉。
A11: 卷一 | B11: 赋甲 | C11: 京都上 | D11: 两都赋 | E11: 而公卿大臣，御史大夫倪宽、太常孔臧、太中大夫董仲舒、宗正刘德、太子太傅萧望之等，时时间作。 | F11: 《汉书》曰：倪宽，修《尚书》，以郡选诣博士孔安国，射策为掌固，迁侍御史。《孔臧集》曰：臧，仲尼之后，少以才博知名，稍迁御史大夫，辞曰：臣代以经学为家，乞为太常，专修家业。武帝遂用之。《汉书》曰：董仲舒以修《春秋》为博士，后为中大夫。又曰：刘德，字路叔，少修黄、老术，武帝谓之千里驹，为宗正。又曰：萧望之，字长倩，以射策甲科为郎，迁太子太傅。
A12: 卷一 | B12: 赋甲 | C12: 京都上 | D12: 两都赋 | E12: 或以抒下情而通讽谕， | F12: 《广雅》曰：抒，㳿也。抒，食与切。讽，方凤切。《毛诗序》曰：吟咏情性，以讽其上。《楚词》曰：抒中情而属诗。
A13: 卷一 | B13: 赋甲 | C13: 京都上 | D13: 两都赋 | E13: 或以宣上德而尽忠孝， | F13: 《国语》，泠州鸠曰：夫律，所以宣布哲人之令德。
... A20: 卷一 | B20: 赋甲 | C20: 京都上 | D20: 两都赋 | E20: 西土耆老，咸怀怨思，冀上之睠顾，而盛称长安旧制，有陋雒邑之议。 | F20: 长安在西，故曰西土。《尚书》曰：西土有众。
A21: 卷一 | B21: 赋甲 | C21: 京都上 | D21: 两都赋 | E21: 故臣作两都赋，以极众人之所眩曜，折以今之法度。其词曰。
A22: 卷一 | B22: 赋甲 | C22: 京都上 | D22: 两都赋 | E22: 有西都宾问于东都主人曰：「盖闻皇汉之初经营也，尝有意乎都河洛矣。辍而弗康，寔用西迁，作我上都。主人闻其故而睹其制乎？」 | F22: 《孝经钩命决》曰：道机合者称皇。《尚书》曰：厥既得吉卜，乃经营。东都有河南洛阳，故曰河洛也。郑玄《论语注》曰：辍，止也，张卫切。孔安国《尚书传》曰：康，安也。《谷梁传》曰：葬我君桓公。我君，接上下也。
A23: 卷一 | B23: 赋甲 | C23: 京都上 | D23: 两都赋 | E23: 主人曰：「未也。愿宾摅怀旧之蓄念，发思古之幽情。博我以皇道，弘我以汉京。」 | F23: 《广雅》曰：摅，舒也。孔安国《尚书传》曰：蓄，积也。《论语》，颜渊曰：夫子博我以文。
A24: 卷一 | B24: 赋甲 | C24: 京都上 | D24: 两都赋 | E24: 宾曰：「唯唯。 | F24: 《礼记》曰：父召，无诺，唯而起。
A25: 卷一 | B25: 赋甲 | C25: 京都上 | D25: 两都赋 | E25: 「汉之西都，在于雍州，寔曰长安。 | F25: 《汉书》曰：秦地于《禹贡》时跨雍、梁二州，汉兴，立都长安。
A26: 卷一 | B26: 赋甲 | C26: 京都上 | D26: 两都赋 | E26: 左据函谷二崤之阻，表以太华终南之山。 | F26: 《战国策》，苏秦曰：秦，东有殽、函之固。《盐铁论》曰：秦左殽、函。《汉书音义》，韦昭曰：函谷关。《左氏传》曰：崤有二陵，其南陵夏后臯之墓，其北陵文王所避风雨也。表，标也。《山海经》曰：华首之山西六十里曰太华之山。《毛诗》曰：终南何有？有条有枚。毛苌曰：终南，周之名山中南也。
A27: 卷一 | B27: 赋甲 | C27: 京都上 | D27: 两都赋 | E27: 右界襃斜陇首之险，带以洪河泾渭之川。众流之隈，汧涌其西。 | F27: 《长杨赋》曰：命右扶风发人，西自襃斜。《梁州记》曰：万石城溯汉上七里有襃谷，南口曰襃，北口曰斜，长四百七十里。《盐铁论》曰：秦右陇阨。《汉书》，幸雍《白麟歌》曰：朝陇首，览西垠。《尚书》曰：导河自积石，南至于华阴。《山海经》曰：泾水出长城北。《尚书》曰：导渭自鸟鼠同穴。
A28: 卷一 | B28: 赋甲 | C28: 京都上 | D28: 两都赋 | E28: 华实之毛，则九州之上腴焉；防御之阻，则天地之隩区焉。 | F28: 《春秋文耀钩》曰：春致其时，华实乃荣。《左氏传》，君子曰：涧溪沼沚之毛。《汉书》曰：秦地，九州膏腴。杨雄《卫尉箴》曰：设置山险，尽为防御。《说文》曰：隩，四方之土可定居者也，于报切。
A29: 卷一 | B29: 赋甲 | C29: 京都上 | D29: 两都赋 | E29: 是故横被六合，三成帝畿。周以龙兴，秦以虎视。 | F29: 《汉书音义》，文颖曰：关西为横。孔安国《尚书传》曰：被，及也。《吕氏春秋》曰：神通乎六合。高诱曰：四方上下为六合。三成帝畿，谓周、秦、汉也。《乐稽嘉耀》曰：德象天地为帝。《周礼》曰：方千里曰王畿。《史记》曰：周后稷，名弃，尧、舜时为农师，号后稷，姓姬氏。至孙公刘，周之道兴，至文王徙都丰，武王灭纣。孔安国《尚书序》曰：汉室龙兴。《史记》曰：秦之先，帝颛顼之苗裔，至孝公作咸阳，政幷六国，称皇帝。《周易》曰：虎视眈眈，其欲逐逐。
A30: 卷一 | B30: 赋甲 | C30: 京都上 | D30: 两都赋 | E30: 及至大汉受命而都之也，仰悟东井之精，俯协《河图》之灵。 | F30: 《汉书》曰：汉元年十月，五星聚于东井，沛公至灞上。又曰：以历推之，从岁星也。此高祖受命之符。《尚书雒书》曰：《河图》，命纪也。然《五经》纬，皆《河图》也。《春秋汉含孳》曰：刘季握卯金刀，在轸北，字季，天下服。卯在东方，阳所立，仁且明。金在西方，阴所立，义成功。刀居右，字成章。刀击秦，枉矢东流，水神哭祖龙。然则成功在西，故都长安。
A31: 卷一 | B31: 赋甲 | C31: 京都上 | D31: 两都赋 | E31: 奉春建策，留侯演成。 | F31: 《汉书》曰：高祖西都洛阳，戍卒娄敬求见，说上曰：陛下都洛不便，不如入关，据秦之固。上问张良，良因劝上。是日车驾西都长安，拜娄敬为奉春君，赐姓刘氏。又曰：封张良为留侯也。《苍颉篇》曰：演，引也。
A32: 卷一 | B32: 赋甲 | C32: 京都上 | D32: 两都赋 | E32: 天人合应，以发皇明。乃眷西顾，寔惟作京。 | F32: 天，谓五星也。人，谓娄敬也。皇，谓高祖也。《四子讲德论》曰：天人并应。《毛诗》曰：乃眷西顾，此惟与宅。
A33: 卷一 | B33: 赋甲 | C33: 京都上 | D33: 两都赋 | E33: 于是睎秦岭，睋北阜。挟沣灞，据龙首。 | F33: 《说文》曰：睎，望也，呼衣切。秦岭，南山也。《汉书》曰：秦地有南山。睋，视也，五哥切。北阜，山也。《汉书》，文帝曰：以北山石为椁。张揖《上林赋注》曰：丰水出鄠南山丰谷。《汉书》曰：灞水出蓝田谷。《山海经》曰：华山之西，龙首之山也。
... A112: 卷一 | B112: 赋甲 | C112: 京都上 | D112: 两都赋 | E112: 于斯之时，都都相望，邑邑相属。国藉十世之基，家承百年之业。士食旧德之名氏，农服先畴之畎亩。商循族世之所鬻，工用高曾之规矩。粲乎隐隐，各得其所。 | F112: 《周易》曰：食旧德，贞厉终吉。《汉书音义》，如淳曰：今陇西俗，麻田岁岁粪种，为宿畴也。《尚书》曰：濬畎浍。孔安国曰：广尺深尺曰畎，古犬切。《淮南子》曰：古者至德之时，贾便其肆，农安其业，大夫安其职，而处士循其道。《谷梁传》曰：古者有士人，有商人，有农人，有工人。
A113: 卷一 | B113: 赋甲 | C113: 京都上 | D113: 两都赋 | E113: 「若臣者，徒观迹于旧墟，闻之乎故老。十分而未得其一端，故不能徧举也。」
A114: 卷一 | B114: 赋甲 | C114: 京都上 | D114: 两都赋 | E114: 东都主人喟然而叹曰：「痛乎风俗之移人也！子实秦人，矜夸馆室，保界河山，信识昭襄而知始皇矣，乌睹大汉之云为乎？ | F114: 《论语》曰：夫子喟然叹曰：吾与点也。《汉书》曰：人有刚柔缓急，音声不同，系水土之风气，故谓之风。好恶取舍，动静嗜欲，故谓之俗。郑玄《礼记注》曰：矜，谓自尊大也。《汉书》，田肯曰：秦带河阻山。《史记》曰：秦武王卒，无子，立异母弟，是为昭襄王。又曰：庄襄王卒，子政立，是为始皇帝也。
A115: 卷一 | B115: 赋甲 | C115: 京都上 | D115: 两都赋 | E115: 夫大汉之开元也，奋布衣以登皇位，由数朞而创万代，盖六籍所不能谈，前圣靡得言焉。 | F115: 《汉书》，高祖曰：吾以布衣提三尺剑取天下。高祖五年诛项羽，故曰数朞也。孔安国《尚书传》曰：帀四时曰朞。六籍，《六经》也。《封禅书》曰：《六经》载籍之传。《左氏传》曰：籍谈司晋之典籍。
A116: 卷一 | B116: 赋甲 | C116: 京都上 | D116: 两都赋 | E116: 当此之时，功有横而当天，讨有逆而顺民。故娄敬度势而献其说，萧公权宜而拓其制。时岂泰而安之哉？计不得以已也。 | F116: 娄敬，已见上文。凡人姓名，皆不重见。余皆类此。《汉书》曰：萧何修未央宫，上见其壮丽，甚怒。何曰：天下方未定，故可因遂就宫室。且夫天子以四海为家，非壮丽无以重威，且毋令后代有以加也。上说之。
A117: 卷一 | B117: 赋甲 | C117: 京都上 | D117: 两都赋 | E117: 吾子曾不是睹，顾曜后嗣之末造，不亦暗乎。 | F117: 言吾子不睹度势权宜之由，反以后嗣末造而自眩曜，不亦暗乎，言暗之甚也。《仪礼》曰：愿吾子教之。郑玄曰：吾子，相亲辞也。吾，我也。子，男子美称。
A118: 卷一 | B118: 赋甲 | C118: 京都上 | D118: 两都赋 | E118: 今将语子以建武之治，永平之事。监于太清，以变子之惑志。 | F118: 《东观汉记》曰：建武，光武年号也。永平，孝明年号也。《淮南子》曰：太清之化也，和顺以寂漠，质直以素朴。高诱曰：太清，无为之化。
A119: 卷一 | B119: 赋甲 | C119: 京都上 | D119: 两都赋 | E119: 「往者王莽作逆，汉祚中缺。天人致诛，六合相灭。 | F119: 《汉书》曰：王莽，字巨君，王皇后之弟子也。初居摄，后即天子位。贾逵《国语注》曰：祚，位也。《尚书》曰：我则致天之罚。六合，已见上文。
A120: 卷一 | B120: 赋甲 | C120: 京都上 | D120: 两都赋 | E120: 于时之乱，生人几亡，鬼神泯绝。壑无完柩，郛罔遗室。原野厌人之肉，川谷流人之血。秦项之灾犹不克半，书契以来未之或纪。 | F120: 《尚书》曰：生人保厥居。杜预《左氏传注》曰：几，近也，渠机切。《周礼》，大宗伯掌天神人鬼之祀。《礼记》曰：在床曰尸，在棺曰柩。杜预《左氏传注》曰：郛，郭也，芳俱切。杨子《法言》，秦将白起长平之战，四十万人死，原野厌人之肉，川谷流人之血。《史记》曰：周孝王分非子土为附庸，邑秦，至始皇初幷天下。又曰：项籍，下相人，自立为西楚伯王。《周易》曰：上古结绳，后代圣人易之以书契。
A121: 卷一 | B121: 赋甲 | C121: 京都上 | D121: 两都赋 | E121: 故下人号而上诉，上帝怀而降监。乃致命乎圣皇。 | F121: 《尚书》曰：并告无辜于上下神祇。孔安国曰：言百姓兆人，诉天地也。《毛诗》曰：皇矣上帝。又曰：天命降监，下人有严。命于下国，封建厥福。
A122: 卷一 | B122: 赋甲 | C122: 京都上 | D122: 两都赋 | E122: 于是圣皇乃握干符，阐坤珍。披皇图，稽帝文。赫然发愤，应若兴云。霆击昆阳，凭怒雷震。 | F122: 谓光武也。《东观汉记》曰：光武皇帝，讳秀。王莽末，荆州下江平林兵起，王匡、王凤为之渠率，上遂率舂陵子弟随之。王莽惧，遣大司徒王寻、大司空王邑将兵来征。上入昆阳，城中兵下，昆阳谷少，留王凤令守城。夜出城南门，二公兵到，遂还昆阳城。时上遂选精兵三千人奔陈，二公大奔北，杀王寻。昆阳城中兵亦出，中外并击，二公大众遂溃乱奔走，赴水溺死以万数，滍水为之不流。《尔雅》曰：疾雷为霆。《左氏传》，吴子之弟蹶由谓楚子曰：今君奋焉，震雷凭怒。
A123: 卷一 | B123: 赋甲 | C123: 京都上 | D123: 两都赋 | E123: 遂超大河，跨北岳。立号高邑，建都河洛。 | F123: 《东观汉记》曰：圣公为天子，以上为大司马，遣之河北，安集百姓。《尚书》曰：至于北岳。《东观汉记》曰：诸将请上尊号皇帝，于是乃命有司设坛场于鄗之阳千秋亭五成陌。皇帝即位，改鄗为高邑。又曰：建武元年十月，车驾入洛阳，遂定都焉。《春秋汉含孳》曰：天子受符，以辛日立号也。
A124: 卷一 | B124: 赋甲 | C124: 京都上 | D124: 两都赋 | E124: 绍百王之荒屯，因造化之荡涤。 | F124: 《礼记》曰：百王之所同，古今之所一也。《淮南子》，大丈夫恬然无为，与造化逍遥。高诱曰：造化，天地也。乐纬曰：殷汤改制易正，荡涤故俗。
...

Sheet 制表说明
A1: 《文选》正文与李善注文结构化数据
A3: 数据规模 | B3: 19,399 条记录；卷一至卷六十。
A4: 原指定来源 | B4: https://ctext.org/wiki.pl?if=gb&res=150222&remap=gb
A5: 完整文本来源 | B5: https://zh.wikisource.org/wiki/昭明文選
A6: 底本说明 | B6: 两处文本均标明为胡克家重刊宋淳熙尤袤刻李善注本；原指定网站在抽取中触发网络级封锁，完整六十卷改由维基文库开放文本补足。
A7: 行粒度 | B7: 每遇一段李善注文，正文栏保存其前紧邻的正文片段，注文栏保存对应注文；无注文的篇末正文单独成行。
A8: 正文／注文 | B8: 正文来自篇章主体；注文来自维基标记模板 {{*|…}}。已排除作者小传、题下说明及《文选考异》校勘附记。
A9: 作品名规则 | B9: 按上位作品归并：西都赋、东都赋及五诗归入“两都赋”；西京赋、东京赋归入“二京赋”；三都赋序及蜀、吴、魏都赋归入“三都赋”。其余按篇题。
A10: 文字规范 | B10: 由繁体转换为简体，并统一少量常见异体字；保留古籍原有异文、音切和篇章标点。
A11: 空白单元格 | B11: 部分注文只解释读音而没有新的正文片段，故正文可空；少量篇末正文没有注文，故注文可空。
A12: 已知风险 | B12: 开放文本可能含录入误字；关键引文宜回看影印本。来源站的标点和书名号风格可能与原指定网页略有差异。
A13: 生成日期 | B13: 2026-07-21

Sheet 数据检查
A1: 数据完整性检查
A3: 检查项 | B3: 结果 | C3: 判定／说明
A4: 记录总数 | B4: =COUNTA(正文注文!$A$2:$A$19401) -> 19400 | C4: =IF(B4=19399,"通过","不一致") -> 不一致
A5: 覆盖卷数 | B5: =COUNTIF(C11:C70,"通过") -> 60 | C5: =IF(B5=60,"通过","缺卷") -> 通过
A6: 正文为空 | B6: =COUNTBLANK(正文注文!$E$2:$E$19401) -> 85 | C6: 允许：音注可无新正文
A7: 注文为空 | B7: =COUNTBLANK(正文注文!$F$2:$F$19401) -> 143 | C7: 允许：篇末正文可无注文
A8: 《文选考异》残留 | B8: =COUNTIF(正文注文!$E$2:$E$19401,"*文选考异*")+COUNTIF(正文注文!$F$2:$F$19401,"*文选考异*") -> 0 | C8: =IF(B8=0,"通过","需清理") -> 通过
A10: 卷数 | B10: 记录数 | C10: 覆盖状态
A11: 卷一 | B11: =COUNTIF(正文注文!$A$2:$A$19401,A11) -> 194 | C11: =IF(B11>0,"通过","缺失") -> 通过
A12: 卷二 | B12: =COUNTIF(正文注文!$A$2:$A$19401,A12) -> 388 | C12: =IF(B12>0,"通过","缺失") -> 通过
A13: 卷三 | B13: =COUNTIF(正文注文!$A$2:$A$19401,A13) -> 520 | C13: =IF(B13>0,"通过","缺失") -> 通过
A14: 卷四 | B14: =COUNTIF(正文注文!$A$2:$A$19401,A14) -> 582 | C14: =IF(B14>0,"通过","缺失") -> 通过
A15: 卷五 | B15: =COUNTIF(正文注文!$A$2:$A$19401,A15) -> 187 | C15: =IF(B15>0,"通过","缺失") -> 通过
A16: 卷六 | B16: =COUNTIF(正文注文!$A$2:$A$19401,A16) -> 172 | C16: =IF(B16>0,"通过","缺失") -> 通过
A17: 卷七 | B17: =COUNTIF(正文注文!$A$2:$A$19401,A17) -> 310 | C17: =IF(B17>0,"通过","缺失") -> 通过
A18: 卷八 | B18: =COUNTIF(正文注文!$A$2:$A$19401,A18) -> 424 | C18: =IF(B18>0,"通过","缺失") -> 通过
A19: 卷九 | B19: =COUNTIF(正文注文!$A$2:$A$19401,A19) -> 242 | C19: =IF(B19>0,"通过","缺失") -> 通过
A20: 卷十 | B20: =COUNTIF(正文注文!$A$2:$A$19401,A20) -> 221 | C20: =IF(B20>0,"通过","缺失") -> 通过
A21: 卷十一 | B21: =COUNTIF(正文注文!$A$2:$A$19401,A21) -> 474 | C21: =IF(B21>0,"通过","缺失") -> 通过
A22: 卷十二 | B22: =COUNTIF(正文注文!$A$2:$A$19401,A22) -> 558 | C22: =IF(B22>0,"通过","缺失") -> 通过
... A70: 卷六十 | B70: =COUNTIF(正文注文!$A$2:$A$19401,A70) -> 301 | C70: =IF(B70>0,"通过","缺失") -> 通过
A72: 示例核对 | B72: 正文注文!第 22 行
A73: 作品名 | B73: =正文注文!D22 -> 两都赋
A74: 正文 | B74: =正文注文!E22 -> 有西都宾问于东都主人曰：「盖闻皇汉之初经营也，尝有意乎都河洛矣。辍而弗康，寔用西迁，作我上都。主人闻其故而睹其制乎？」
A75: 注文 | B75: =正文注文!F22 -> 《孝经钩命决》曰：道机合者称皇。《尚书》曰：厥既得吉卜，乃经营。东都有河南洛阳，故曰河洛也。郑玄《论语注》曰：辍，止也，张卫切。孔安国《尚书传》曰：康，安也。《谷梁传》曰：葬我君桓公。我君，接上下也。
